#usda 1.0
(
    defaultPrim = "RockerBogie"
    upAxis = "Y"
    metersPerUnit = 1
)

# G5 — rocker-bogie chassis with a differential coupling.
#
# A complete physical joint-based rocker-bogie suspension with 6 motorized wheels:
#   - Two side rockers (RockerL/R) hinge to the chassis on the X axis.
#   - Two bogies (BogieL/R) hinge to the rear of the rockers on the X axis.
#   - Six wheels (FL/FR/ML/MR/RL/RR) reference the reusable motorized wheel components.
#   - The differential coupling softly enforces: θ_left + θ_right → 0.
#   - Controllable via keyboard/UI through PhysxVehicleTankDifferentialAPI.
#
# FOR PARAMETER EDITING GUIDE: See the accompanying README.md in this directory.

def Xform "RockerBogie" (
    # An ASSEMBLY: a model built out of other models. Its wheels are component models
    # that arrive by reference, and USD forbids a `component` from containing them.
    kind = "assembly"
    prepend apiSchemas = [
        "PhysicsRigidBodyAPI", "PhysxRigidBodyAPI",
        "PhysicsMassAPI",
        "PhysicsArticulationRootAPI",
        "PhysxVehicleContextAPI",
        "PhysxVehicleTankDifferentialAPI", "LunCoCatalogAPI"
    ]
    # The ON-BOARD COMPUTER, as a second reference arc — the rover's COMMAND
    # SURFACE (`throttle`/`steer`/`brake`). Ships with the chassis; without one
    # this rover accepts no commands at all. See `skid_rover.usda`.
    prepend references = @lunco://components/avionics/obc.usda@</OBC>
    prepend variantSets = ["power", "thermal"]
    variants = {
        string power = "infinite"
        string thermal = "none"
    }
)
{
    uniform bool lunco:spawnable = true
    # --- VEHICLE MASS & DAMPING ---
    #
    # 1.8 m body over a 2.4 m wheelbase and a 2.4 m track, on 0.8 m-diameter ×
    # 0.4 m-wide wheels. Belly clearance follows from the geometry rather than
    # being authored: every wheel centre sits 0.6 m below the chassis origin, so a
    # 0.4 m wheel puts the ground at -1.0 and the hull underside (half-height 0.2)
    # 0.8 m above it.
    #
    # ⚠ THE WHEEL IS BIG ON PURPOSE — IT IS SIZED TO THE TERRAIN, NOT TO A PHOTO.
    # It was cut to 0.25 m on 2026-07-22 for looks, because 0.8 m wheels under a
    # 1.8 m body read as a cart on tractor tyres and Curiosity's real wheel is
    # 0.5 m. That broke the summer-school traverse: the rover stopped being able to
    # get up the crater walls. Nothing about traction changed (the slope limit is
    # atan(μ) and μ lives on the tyre) — it was GEOMETRY. That scene's terrain
    # carries an `overzoom` craterlet layer at 0.4–6 m feature size and a `rocks`
    # layer at density 25, and a wheel climbs an obstacle roughly its own radius:
    # 0.4 m rolls over that terrain, 0.25 m catches on it. Ground clearance fell
    # from 0.8 m to 0.65 m at the same time, so the hull grounded sooner too.
    #
    # The WIDTH is where the proportions were fixed instead — 0.3 → 0.4 m, so the
    # wheel reads as a wide lunar wheel rather than a thin disc, with the radius
    # left at the size the terrain needs. Curiosity's proportions are not a target
    # here; Curiosity does not drive on this ground.
    #
    # Mass budget: 300 (hull) + 2×50 (rockers) + 2×30 (bogies) + 6×12 (wheels)
    # + 6×8 (motors) + 6×4 (gearboxes) ≈ 604 kg — between MER's 185 kg and MSL's
    # 899 kg, and just under Lunokhod's 756 kg.
    #
    # ⚠ THE HULL MASS IS NO LONGER PINNED BY THE DIFFERENTIAL — it is simply not yet
    # PROVEN above 300 kg. The coupling used to fail outright at 400 kg (29%
    # residual); since it became a mass-independent implicit solve that same 400 kg
    # mirrors at 8.6%, better than 300 kg ever managed before. What stops the number
    # moving today is the TEST, not the vehicle: `scenes/tests/rocker_bogie.usda`'s
    # 0.7 m step cannot hold a heavier rover — it slides off, and the rig then has
    # nothing to measure. Give that rig a step it can hold and this is free.
    # Read the `Differential` prim and `RockerL` before moving any of these.
    # The wheels are the one free mass: they hang off the arms as their own bodies.
    #
    # ⚠ Mass is NOT what sets the difficulty ladder. The tiers are traction-limited
    # (slope limit → atan(μ), mass-free) and nowhere near the ~15 kN of axle thrust
    # the powertrain can put down, so the μ margins in `variants/rover_*.usda`
    # survive a mass edit. Do not "rebalance" them against this number.
    float physics:mass = 300.0
    float lunco:spawnLift = 1.5

    # ── THERE IS NO AIR. DRAG LIVES IN THE PARTS. ───────────────────────────
    # Body damping is a fluid model: a force proportional to velocity, applied to
    # the hull, standing in for air the Moon does not have. This carried 0.4 linear
    # and 2.0 angular — at 604 kg and 1.4 m/s the linear term alone was ~340 N of
    # invented headwind, and the angular term was a hand on the steering that no
    # part accounted for.
    #
    # Both are now ~0 and the losses are authored where the hardware loses them:
    #   · `physxVehicleWheel:dampingRate` = 0.45 N·m·s per wheel — the sealed
    #     dry-lubricated bearing plus regolith rolling resistance (`wheel.usda`).
    #   · `lunco:gearbox:efficiency` = 0.85 — a cold multi-stage harmonic drive.
    #   · tyre μ — lateral friction is what actually resists a yaw, and it does:
    #     with angular damping gone the rover still turns flat (2.8° peak roll
    #     under full steer at 0.6 throttle, measured) rather than spinning out.
    #
    # 0.05 rather than a hard 0 on the angular term: a rigid body with literally no
    # rotational damping is a solver liability, and 0.05 is small enough to be lost
    # in the bearing drag. It is a numerical floor, not a physical claim.
    #
    # ⚠ Measured: removing BOTH changed terminal speed by under 2% (3.50 → 3.59 m/s).
    # The body damping was never the speed limiter — see `Motor_FL` for what is.
    float physxRigidBody:linearDamping = 0.0
    float physxRigidBody:angularDamping = 0.05

    # The two bank actuator ports, as attributes the motors CONNECT to. Declaring
    # them here gives each `inputs:demand.connect` a real property to resolve to, so
    # the binding is PCP-resolved and path-translated through the reference arcs
    # instead of matched by name. Without them every `Motor_*` on this chassis wires
    # to a property that does not exist and the cosim bridge drops the value with
    # "connection targets unknown input port 'drive_left'" — the same declaration
    # `six_wheel_rover.usda` has always carried.
    float outputs:drive_left = 0.0
    float outputs:drive_right = 0.0

    # Intent->port control (stage 2): shared rover profile as a child `references`
    # arc so it composes through a spawn/reference like the wheels.
    def "Controls" (
        prepend references = @lunco://vessels/control_profiles.usda@</RoverControls>
    )
    {
    }

    # --- CHASSIS GEOMETRY & VISUALS ---
    # Main body — the shared box chassis component (collider + panelised hull
    # material), referenced INTO this prim so the name `Body` and every local
    # opinion below survive. Its own scale wins over the component default.
    def Cube "Body" (
        prepend references = @lunco://components/mobility/chassis/box_chassis.usda@</Chassis>
    )
    {
        double3 xformOp:scale = (1.2, 0.4, 1.8)
        # NASA-ish white-grey — the science-platform archetype. Colour is
        # `primvars:displayColor` and nothing else; the hull shader consumes it
        # as the base paint.
        color3f[] primvars:displayColor = [(0.9, 0.9, 0.88)]
        # Gold accent, keeping the solar-foil heritage of the original body.
        over "HullLook"
        {
            over "Shader"
            {
                color3f inputs:accent_color = (0.85, 0.7, 0.2)
            }
        }
    }

    # Slanted Solar panel deck on top of the chassis
    def Cube "SolarDeck"
    {
        double size = 1.0
        double3 xformOp:translate = (0.0, 0.21, 0.0)
        double3 xformOp:scale = (1.3, 0.02, 1.9)
        uniform token[] xformOpOrder = ["xformOp:translate", "xformOp:scale"]
        color3f[] primvars:displayColor = [(0.05, 0.05, 0.2)]
        bool physics:collisionEnabled = false
    }

    # High-gain antenna — the catalogue dish, referenced. It used to be a bare
    # cylinder-on-a-stick here; the project has exactly one antenna now and this is
    # it. `lunco:linkNode` rides in with the component, so a rocker-bogie is a
    # connectivity endpoint out of the box — author `lunco:link:class` /
    # `minElevationDeg` on this prim per scene.
    #
    # ⚠ THIS IS THE ROVER'S ONLY ANTENNA. A scene that wants a link node on a
    # rocker-bogie authors an `over "Antenna"` here — it does NOT add a second
    # `radio.usda`/`antenna.usda` child. `radio.usda` REFERENCES this same dish, so
    # a scene-side comms prim draws a whole second reflector beside this one (which
    # is exactly what the space-school traverse scene used to do, back when this
    # chassis was `six_wheel_rover` and genuinely had none).
    #
    # MOUNTED ON THE REAR DECK, on the centreline-left, clear of the forward
    # science mast at z = -0.6 (forward is -Z: that is where the headlights point).
    # s = 0.45 ⇒ a 0.52 m dish on a 0.5 m stalk — big enough to read as a high-gain
    # at rover scale, short enough to stay inside the roll envelope.
    def "Antenna" (
        prepend references = @lunco://components/comms/antenna.usda@</CommsAntenna>
    )
    {
        string lunco:link:class = "rover"
        double3 xformOp:translate = (-0.35, 0.22, 0.6)
        uniform token[] xformOpOrder = ["xformOp:translate"]

        over "Mast"
        {
            double radius = 0.02
            double height = 0.5
            double3 xformOp:translate = (0.0, 0.25, 0.0)
            color3f[] primvars:displayColor = [(0.6, 0.6, 0.6)]
        }
        over "DishHead"
        {
            double3 xformOp:translate = (0.0, 0.5, 0.0)
            # Parked high-gain: 25 deg off the zenith, tipped REARWARD (+X rotation
            # swings the boresight toward +Z) and canted outboard away from the
            # science mast. Rearward matters: the chase camera sits behind and above
            # a driven rover, so a forward-leaning dish shows that camera nothing but
            # the back of the reflector — which is what -40 did, and why the antenna
            # read as a white sliver rather than as a dish.
            double3 xformOp:rotateXYZ = (25.0, -20.0, 0.0)
            double3 xformOp:scale = (0.45, 0.45, 0.45)
        }
    }

    # Instrument platform / science mast
    def Cylinder "Mast"
    {
        uniform token axis = "Y"
        double radius = 0.04
        double height = 0.8
        double3 xformOp:translate = (0.0, 0.5, -0.6)
        uniform token[] xformOpOrder = ["xformOp:translate"]
        color3f[] primvars:displayColor = [(0.6, 0.6, 0.6)]
        bool physics:collisionEnabled = false
    }

    def Cube "CameraHead"
    {
        double size = 1.0
        double3 xformOp:scale = (0.2, 0.15, 0.15)
        double3 xformOp:translate = (0.0, 0.95, -0.6)
        uniform token[] xformOpOrder = ["xformOp:translate", "xformOp:scale"]
        color3f[] primvars:displayColor = [(0.15, 0.15, 0.15)]
        bool physics:collisionEnabled = false
    }

    # Headlights
    def Xform "Headlight_L" (
        prepend references = @lunco://components/lights/headlight.usda@</Headlight>
    )
    {
        double3 xformOp:translate = (-0.5, 0.1, -0.9)
        double3 xformOp:rotateXYZ = (-15, 0, 0)
        uniform token[] xformOpOrder = ["xformOp:translate", "xformOp:rotateXYZ"]
    }

    def Xform "Headlight_R" (
        prepend references = @lunco://components/lights/headlight.usda@</Headlight>
    )
    {
        double3 xformOp:translate = (0.5, 0.1, -0.9)
        double3 xformOp:rotateXYZ = (-15, 0, 0)
        uniform token[] xformOpOrder = ["xformOp:translate", "xformOp:rotateXYZ"]
    }

    # ── Left rocker ─────────────────────────────────────────────────────────
    def Xform "RockerL" (
        prepend apiSchemas = ["PhysicsRigidBodyAPI", "PhysxRigidBodyAPI", "PhysicsMassAPI"]
    )
    {
        # ⚠ LIGHTENING THE ARMS ONCE MADE THE LINKAGE RING. 25 kg is the honest
        # structural mass for a 2.4 m titanium rocker, and it was tried (2026-07-22,
        # bogies at 18 kg to match): the differential never settled, wandering
        # ±0.03 rad and 1–3 deg of chassis tilt for the full 10 s of
        # `scenarios/tests/rocker_bogie.usda` instead of holding steady. It PASSED
        # while visibly shivering, which is the worst kind of green.
        #
        # That was measured against the EXPLICIT coupling, whose response scaled as
        # √(k/I) and so ran into the solver's ringing band as I fell. The coupling is
        # implicit and inertia-normalised now, which is exactly the mechanism that
        # made this fail — so lighter arms may well be fine today. It has NOT been
        # re-measured. Re-run both rocker-bogie scenes and watch the per-second
        # timeline for wander, not just the verdict, before trusting it.
        float physics:mass = 50.0
        float3 physics:diagonalInertia = (30.0, 30.0, 3.0)
        double3 xformOp:translate = (-0.9, -0.2, 0.0)
        uniform token[] xformOpOrder = ["xformOp:translate"]

        # Rocker main forward-down link (pivots down/forward to front wheel)
        # Length: 1.265m, Midpoint: (0.0, -0.2, -0.6), Rotated: -18.43 deg about X
        def Cylinder "FrontLink"
        {
            uniform token axis = "Z"
            double radius = 0.06
            double height = 1.265
            double3 xformOp:translate = (0.0, -0.2, -0.6)
            double3 xformOp:rotateXYZ = (-18.43, 0.0, 0.0)
            uniform token[] xformOpOrder = ["xformOp:translate", "xformOp:rotateXYZ"]
            color3f[] primvars:displayColor = [(0.35, 0.35, 0.38)]
            bool physics:collisionEnabled = false
        }

        # Rocker rear-down link (pivots down/backward to bogie hinge)
        # Length: 0.632m, Midpoint: (0.0, -0.1, 0.3), Rotated: 18.43 deg about X
        def Cylinder "RearLink"
        {
            uniform token axis = "Z"
            double radius = 0.06
            double height = 0.632
            double3 xformOp:translate = (0.0, -0.1, 0.3)
            double3 xformOp:rotateXYZ = (18.43, 0.0, 0.0)
            uniform token[] xformOpOrder = ["xformOp:translate", "xformOp:rotateXYZ"]
            color3f[] primvars:displayColor = [(0.35, 0.35, 0.38)]
            bool physics:collisionEnabled = false
        }

        # Outward X-axis axle to front wheel
        def Cylinder "Axle"
        {
            uniform token axis = "X"
            double radius = 0.04
            double height = 0.25
            double3 xformOp:translate = (-0.125, -0.4, -1.2)
            uniform token[] xformOpOrder = ["xformOp:translate"]
            color3f[] primvars:displayColor = [(0.6, 0.6, 0.6)]
            bool physics:collisionEnabled = false
        }

        # Rocker joint cover housing
        def Cylinder "JointCover"
        {
            uniform token axis = "X"
            double radius = 0.12
            double height = 0.12
            double3 xformOp:translate = (0.0, 0.0, 0.0)
            uniform token[] xformOpOrder = ["xformOp:translate"]
            color3f[] primvars:displayColor = [(0.85, 0.7, 0.2)]
            bool physics:collisionEnabled = false
        }

        # Simplified box collider for the rocker arm (clears the bogie space).
        # `visibility = "invisible"` — collision-only: the loader would otherwise
        # render this as a white bar (no displayColor → Color::WHITE fallback).
        def Cube "Collider" (
            prepend apiSchemas = ["PhysicsCollisionAPI"]
        )
        {
            double size = 1.0
            double3 xformOp:scale = (0.12, 0.12, 1.2)
            double3 xformOp:translate = (0.0, -0.2, -0.6)
            uniform token[] xformOpOrder = ["xformOp:translate", "xformOp:scale"]
            token visibility = "invisible"
            bool physics:collisionEnabled = true
        }

        # Front Left Wheel
        def Cylinder "Wheel_FL" (
            prepend references = [
                @lunco://components/mobility/wheel.usda@</Wheel>,
                @lunco://components/mobility/suspensions/rocker.usda@</Suspension>,
            ]
        )
        {
            uniform token axis = "X"
            # 0.5 m diameter × 0.4 m wide — Curiosity's wheel, and the reason this
            # rover stopped looking like a cart on tractor tyres.
            #
            # ⚠ `physxVehicleWheel:radius` IS A SECOND SPELLING OF THE SAME RADIUS
            # and it is the one the dynamics read (`update_wheel_spin`: I = ½mr²,
            # τ_traction = F·r). `wheel.usda` defaults it to 0.4, so a geometry-only
            # resize leaves the physics turning an invisible 0.8 m wheel. Author both.
            double radius = 0.4
            double height = 0.4
            float physxVehicleWheel:radius = 0.4
            # An aluminium spun wheel with a flexure sidewall, not the 25 kg
            # placeholder `wheel.usda` ships as its catalogue default.
            float physics:mass = 12.0
            double3 xformOp:translate = (-0.3, -0.4, -1.2)
            uniform token[] xformOpOrder = ["xformOp:translate"]
            color3f[] primvars:displayColor = [(0.15, 0.15, 0.15)]

            # --- WHEEL DYNAMICS CONFIGURATION ---
            int lunco:wheel:index = 0
        }

        # Motor + reduction for the front-left wheel. A CHILD OF THE ROCKER, not of
        # the chassis: the rocker is its own rigid body, and a motor bolted to the
        # arm must swing with the arm. Placed inboard of the wheel so its housing
        # never overlaps the wheel collider.
        #
        #   τ_axle = stallTorque · (1 − ω_shaft/noLoadSpeed) · ratio · efficiency · demand
        # clamped at the gearbox's `maxOutputTorque`; axle no-load speed =
        # 14400/1200 = 12 rad/s. Wheel index 0 is even ⇒ `drive_left`, the same
        # index-parity channel the wheel itself binds.
        def Xform "Motor_FL" (
            prepend references = @lunco://components/mobility/motor.usda@</Motor>
        )
        {
            # ── A DRIVE ACTUATOR LIVES ON THE AXLE IT TURNS ─────────────────────
            # Both housings are ON THE WHEEL'S AXIS — same y, same z as Wheel_FL —
            # with the rocker's own structure between them: motor bolted to the
            # arm's INBOARD face, harmonic drive on the OUTBOARD face driving the
            # hub. That is the MER/MSL arrangement and it is what the wiring
            # already claims (`drivenWheel` → this wheel, `Motor.outputs:torque` →
            # this gearbox).
            #
            # They used to sit at x = ±0.3/±0.15 — 0.9 m inboard of the wheel,
            # floating in the middle of the vehicle, driving a hub they did not
            # touch.
            #
            # ⚠ AND THEY MUST BE TURNED. `motor.usda`/`gearbox.usda` draw `Body` as
            # a bare `Cylinder` with no `axis`, so it defaults to Z — fore-and-aft,
            # broadside to the axle. The component cannot fix this: a wheel's axis
            # is the VESSEL's decision (Rucheyok's wheels are Z-forward), so the
            # rotation belongs on the instance, here, where `axis = "X"` is known.
            double3 xformOp:translate = (0.1, -0.4, -1.2)
            double3 xformOp:rotateXYZ = (0.0, 90.0, 0.0)
            uniform token[] xformOpOrder = ["xformOp:translate", "xformOp:rotateXYZ"]
            prepend rel lunco:motor:drivenWheel = </RockerBogie/RockerL/Wheel_FL>
            float inputs:demand.connect = </RockerBogie.outputs:drive_left>

            # ── THE SPEED KNOB. THE NO-LOAD FIGURE IS NOT THE ROAD SPEED. ───────
            # The axle's free-spin cap is `noLoadSpeed / ratio` — the ONE no-load
            # speed both wheel realizations obey (`wheel.usda`). Here that is
            # 14 400 / 1200 = 12 rad/s, i.e. 4.8 m/s of WHEEL RIM speed.
            #
            # THE ROVER DOES NOT GO 4.8 m/s, AND THAT IS THE POINT. Drive torque
            # rolls off as (1 − ω/ω_noload) while the parts' friction grows with ω,
            # so the vehicle settles where the two cross — short of the ceiling, and
            # NOT in proportion to it. Measured at full throttle on flat ground
            # (headless `sandbox --api`, position sampled every 2 s), on the
            # `rover_medium` tier that the summer school actually drives:
            #
            #     noLoadSpeed   terminal (r = 0.4 m, worn tyres)
            #       14 400        2.71 m/s  ≈ 9.8 km/h   ← authored
            #       23 400        5.72 m/s  ≈ 20.6 km/h
            #
            # ⚠ SPEED IS NOT SEPARABLE FROM WHEEL RADIUS — the same 23 400 gave only
            # 3.59 m/s on the 0.25 m wheels this rover briefly wore, and 1.42 m/s at
            # 13 200. Every figure above is void if the radius moves. MEASURE, never
            # derive: the response is non-linear (doubling 13 200 → 26 400 TRIPLED
            # terminal speed), and deriving "12 rad/s × 0.25 m = 2.75 m/s" from the
            # arithmetic is exactly the mistake that once shipped a rover doing half
            # its claimed speed.
            #
            # 14 400 is `motor.usda`'s catalogue default — this rover is simply
            # running the stock motor. It was briefly geared to Lunokhod's real
            # 2.0 km/h (2 640), which is authentic and unusable: it turned the
            # school's 2.7 km round trip into a multi-hour wait.
            #
            # SPEED ONLY. `stallTorque` is untouched, so axle torque
            # (stallTorque · 1200 · 0.85) and with it the whole difficulty ladder in
            # `variants/rover_*.usda` is exactly what it was. Buying speed by
            # cutting the gearbox ratio instead would throw the torque away with it.
            float lunco:motor:noLoadSpeed = 14400.0
        }

        def Xform "Gearbox_FL" (
            prepend references = @lunco://components/mobility/gearbox.usda@</Gearbox>
        )
        {
            # Outboard face of the arm, on the axle, feeding the hub. See Motor_FL.
            double3 xformOp:translate = (-0.055, -0.4, -1.2)
            double3 xformOp:rotateXYZ = (0.0, 90.0, 0.0)
            uniform token[] xformOpOrder = ["xformOp:translate", "xformOp:rotateXYZ"]
            float inputs:torque.connect = </RockerBogie/RockerL/Motor_FL.outputs:torque>
        }
    }

    # ── Right rocker ────────────────────────────────────────────────────────
    def Xform "RockerR" (
        prepend apiSchemas = ["PhysicsRigidBodyAPI", "PhysxRigidBodyAPI", "PhysicsMassAPI"]
    )
    {
        # ⚠ LIGHTENING THE ARMS ONCE MADE THE LINKAGE RING. 25 kg is the honest
        # structural mass for a 2.4 m titanium rocker, and it was tried (2026-07-22,
        # bogies at 18 kg to match): the differential never settled, wandering
        # ±0.03 rad and 1–3 deg of chassis tilt for the full 10 s of
        # `scenarios/tests/rocker_bogie.usda` instead of holding steady. It PASSED
        # while visibly shivering, which is the worst kind of green.
        #
        # That was measured against the EXPLICIT coupling, whose response scaled as
        # √(k/I) and so ran into the solver's ringing band as I fell. The coupling is
        # implicit and inertia-normalised now, which is exactly the mechanism that
        # made this fail — so lighter arms may well be fine today. It has NOT been
        # re-measured. Re-run both rocker-bogie scenes and watch the per-second
        # timeline for wander, not just the verdict, before trusting it.
        float physics:mass = 50.0
        float3 physics:diagonalInertia = (30.0, 30.0, 3.0)
        double3 xformOp:translate = (0.9, -0.2, 0.0)
        uniform token[] xformOpOrder = ["xformOp:translate"]

        def Cylinder "FrontLink"
        {
            uniform token axis = "Z"
            double radius = 0.06
            double height = 1.265
            double3 xformOp:translate = (0.0, -0.2, -0.6)
            double3 xformOp:rotateXYZ = (-18.43, 0.0, 0.0)
            uniform token[] xformOpOrder = ["xformOp:translate", "xformOp:rotateXYZ"]
            color3f[] primvars:displayColor = [(0.35, 0.35, 0.38)]
            bool physics:collisionEnabled = false
        }

        def Cylinder "RearLink"
        {
            uniform token axis = "Z"
            double radius = 0.06
            double height = 0.632
            double3 xformOp:translate = (0.0, -0.1, 0.3)
            double3 xformOp:rotateXYZ = (18.43, 0.0, 0.0)
            uniform token[] xformOpOrder = ["xformOp:translate", "xformOp:rotateXYZ"]
            color3f[] primvars:displayColor = [(0.35, 0.35, 0.38)]
            bool physics:collisionEnabled = false
        }

        def Cylinder "Axle"
        {
            uniform token axis = "X"
            double radius = 0.04
            double height = 0.25
            double3 xformOp:translate = (0.125, -0.4, -1.2)
            uniform token[] xformOpOrder = ["xformOp:translate"]
            color3f[] primvars:displayColor = [(0.6, 0.6, 0.6)]
            bool physics:collisionEnabled = false
        }

        def Cylinder "JointCover"
        {
            uniform token axis = "X"
            double radius = 0.12
            double height = 0.12
            double3 xformOp:translate = (0.0, 0.0, 0.0)
            uniform token[] xformOpOrder = ["xformOp:translate"]
            color3f[] primvars:displayColor = [(0.85, 0.7, 0.2)]
            bool physics:collisionEnabled = false
        }

        # Simplified box collider for the rocker arm (clears the bogie space).
        # `visibility = "invisible"` — collision-only: the loader would otherwise
        # render this as a white bar (no displayColor → Color::WHITE fallback).
        def Cube "Collider" (
            prepend apiSchemas = ["PhysicsCollisionAPI"]
        )
        {
            double size = 1.0
            double3 xformOp:scale = (0.12, 0.12, 1.2)
            double3 xformOp:translate = (0.0, -0.2, -0.6)
            uniform token[] xformOpOrder = ["xformOp:translate", "xformOp:scale"]
            token visibility = "invisible"
            bool physics:collisionEnabled = true
        }

        # Front Right Wheel
        def Cylinder "Wheel_FR" (
            prepend references = [
                @lunco://components/mobility/wheel.usda@</Wheel>,
                @lunco://components/mobility/suspensions/rocker.usda@</Suspension>,
            ]
        )
        {
            uniform token axis = "X"
            double radius = 0.4
            double height = 0.4
            float physxVehicleWheel:radius = 0.4
            float physics:mass = 12.0
            double3 xformOp:translate = (0.3, -0.4, -1.2)
            uniform token[] xformOpOrder = ["xformOp:translate"]
            color3f[] primvars:displayColor = [(0.15, 0.15, 0.15)]

            int lunco:wheel:index = 1
        }

        # Wheel index 1 is odd ⇒ `drive_right`. Mirror of the left rocker.
        def Xform "Motor_FR" (
            prepend references = @lunco://components/mobility/motor.usda@</Motor>
        )
        {
            # Mirror of the left arm — on the axle, arm between motor and gearbox,
            # both turned onto X. See Motor_FL.
            double3 xformOp:translate = (-0.1, -0.4, -1.2)
            double3 xformOp:rotateXYZ = (0.0, 90.0, 0.0)
            uniform token[] xformOpOrder = ["xformOp:translate", "xformOp:rotateXYZ"]
            prepend rel lunco:motor:drivenWheel = </RockerBogie/RockerR/Wheel_FR>
            float inputs:demand.connect = </RockerBogie.outputs:drive_right>
            # 12.9 km/h measured — see Motor_FL. All six must
            # agree, or the fast wheels drag the slow ones and every wheel scrubs.
            float lunco:motor:noLoadSpeed = 14400.0
        }

        def Xform "Gearbox_FR" (
            prepend references = @lunco://components/mobility/gearbox.usda@</Gearbox>
        )
        {
            double3 xformOp:translate = (0.055, -0.4, -1.2)
            double3 xformOp:rotateXYZ = (0.0, 90.0, 0.0)
            uniform token[] xformOpOrder = ["xformOp:translate", "xformOp:rotateXYZ"]
            float inputs:torque.connect = </RockerBogie/RockerR/Motor_FR.outputs:torque>
        }
    }

    # ── Left bogie ──────────────────────────────────────────────────────────
    def Xform "BogieL" (
        prepend apiSchemas = ["PhysicsRigidBodyAPI", "PhysxRigidBodyAPI", "PhysicsMassAPI"]
    )
    {
        # The shorter, lighter member of the pair — and, like the rocker, kept heavy
        # on purpose. See RockerL for what lightening it did to the differential.
        float physics:mass = 30.0
        float3 physics:diagonalInertia = (15.0, 15.0, 1.5)
        double3 xformOp:translate = (-0.9, -0.4, 0.6)
        uniform token[] xformOpOrder = ["xformOp:translate"]

        # Bogie front-down link (goes down/forward to middle wheel)
        # Length: 0.447m, Midpoint: (0.0, -0.1, -0.2), Rotated: -26.57 deg about X
        def Cylinder "FrontLink"
        {
            uniform token axis = "Z"
            double radius = 0.05
            double height = 0.447
            double3 xformOp:translate = (0.0, -0.1, -0.2)
            double3 xformOp:rotateXYZ = (-26.57, 0.0, 0.0)
            uniform token[] xformOpOrder = ["xformOp:translate", "xformOp:rotateXYZ"]
            color3f[] primvars:displayColor = [(0.45, 0.45, 0.48)]
            bool physics:collisionEnabled = false
        }

        # Bogie rear-down link (goes down/backward to rear wheel)
        # Length: 0.632m, Midpoint: (0.0, -0.1, 0.3), Rotated: 18.43 deg about X
        def Cylinder "RearLink"
        {
            uniform token axis = "Z"
            double radius = 0.05
            double height = 0.632
            double3 xformOp:translate = (0.0, -0.1, 0.3)
            double3 xformOp:rotateXYZ = (18.43, 0.0, 0.0)
            uniform token[] xformOpOrder = ["xformOp:translate", "xformOp:rotateXYZ"]
            color3f[] primvars:displayColor = [(0.45, 0.45, 0.48)]
            bool physics:collisionEnabled = false
        }

        # Axle to middle wheel
        def Cylinder "MiddleAxle"
        {
            uniform token axis = "X"
            double radius = 0.035
            double height = 0.25
            double3 xformOp:translate = (-0.125, -0.2, -0.4)
            uniform token[] xformOpOrder = ["xformOp:translate"]
            color3f[] primvars:displayColor = [(0.6, 0.6, 0.6)]
            bool physics:collisionEnabled = false
        }

        # Axle to rear wheel
        def Cylinder "RearAxle"
        {
            uniform token axis = "X"
            double radius = 0.035
            double height = 0.25
            double3 xformOp:translate = (-0.125, -0.2, 0.6)
            uniform token[] xformOpOrder = ["xformOp:translate"]
            color3f[] primvars:displayColor = [(0.6, 0.6, 0.6)]
            bool physics:collisionEnabled = false
        }

        # Joint cover housing
        def Cylinder "JointCover"
        {
            uniform token axis = "X"
            double radius = 0.1
            double height = 0.1
            double3 xformOp:translate = (0.0, 0.0, 0.0)
            uniform token[] xformOpOrder = ["xformOp:translate"]
            color3f[] primvars:displayColor = [(0.85, 0.7, 0.2)]
            bool physics:collisionEnabled = false
        }

        # Simplified box collider (collision-only, hidden — see RockerL/Collider).
        def Cube "Collider" (
            prepend apiSchemas = ["PhysicsCollisionAPI"]
        )
        {
            double size = 1.0
            double3 xformOp:scale = (0.1, 0.1, 1.2)
            double3 xformOp:translate = (0.0, -0.1, 0.1)
            uniform token[] xformOpOrder = ["xformOp:translate", "xformOp:scale"]
            token visibility = "invisible"
            bool physics:collisionEnabled = true
        }

        # Middle Left Wheel
        def Cylinder "Wheel_ML" (
            prepend references = [
                @lunco://components/mobility/wheel.usda@</Wheel>,
                @lunco://components/mobility/suspensions/rocker.usda@</Suspension>,
            ]
        )
        {
            uniform token axis = "X"
            double radius = 0.4
            double height = 0.4
            float physxVehicleWheel:radius = 0.4
            float physics:mass = 12.0
            double3 xformOp:translate = (-0.3, -0.2, -0.4)
            uniform token[] xformOpOrder = ["xformOp:translate"]
            color3f[] primvars:displayColor = [(0.15, 0.15, 0.15)]

            int lunco:wheel:index = 2
        }

        # Rear Left Wheel
        def Cylinder "Wheel_RL" (
            prepend references = [
                @lunco://components/mobility/wheel.usda@</Wheel>,
                @lunco://components/mobility/suspensions/rocker.usda@</Suspension>,
            ]
        )
        {
            uniform token axis = "X"
            double radius = 0.4
            double height = 0.4
            float physxVehicleWheel:radius = 0.4
            float physics:mass = 12.0
            double3 xformOp:translate = (-0.3, -0.2, 0.6)
            uniform token[] xformOpOrder = ["xformOp:translate"]
            color3f[] primvars:displayColor = [(0.15, 0.15, 0.15)]

            int lunco:wheel:index = 4
        }

        # Two motors on this bogie — indices 2 and 4, both even ⇒ `drive_left`.
        def Xform "Motor_ML" (
            prepend references = @lunco://components/mobility/motor.usda@</Motor>
        )
        {
            # On the axle, arm between motor and gearbox, turned onto X. See Motor_FL.
            double3 xformOp:translate = (0.1, -0.2, -0.4)
            double3 xformOp:rotateXYZ = (0.0, 90.0, 0.0)
            uniform token[] xformOpOrder = ["xformOp:translate", "xformOp:rotateXYZ"]
            prepend rel lunco:motor:drivenWheel = </RockerBogie/BogieL/Wheel_ML>
            float inputs:demand.connect = </RockerBogie.outputs:drive_left>
            float lunco:motor:noLoadSpeed = 14400.0   # 12.9 km/h — see Motor_FL
        }

        def Xform "Gearbox_ML" (
            prepend references = @lunco://components/mobility/gearbox.usda@</Gearbox>
        )
        {
            double3 xformOp:translate = (-0.055, -0.2, -0.4)
            double3 xformOp:rotateXYZ = (0.0, 90.0, 0.0)
            uniform token[] xformOpOrder = ["xformOp:translate", "xformOp:rotateXYZ"]
            float inputs:torque.connect = </RockerBogie/BogieL/Motor_ML.outputs:torque>
        }

        def Xform "Motor_RL" (
            prepend references = @lunco://components/mobility/motor.usda@</Motor>
        )
        {
            # On the axle, arm between motor and gearbox, turned onto X. See Motor_FL.
            double3 xformOp:translate = (0.1, -0.2, 0.6)
            double3 xformOp:rotateXYZ = (0.0, 90.0, 0.0)
            uniform token[] xformOpOrder = ["xformOp:translate", "xformOp:rotateXYZ"]
            prepend rel lunco:motor:drivenWheel = </RockerBogie/BogieL/Wheel_RL>
            float inputs:demand.connect = </RockerBogie.outputs:drive_left>
            float lunco:motor:noLoadSpeed = 14400.0   # 12.9 km/h — see Motor_FL
        }

        def Xform "Gearbox_RL" (
            prepend references = @lunco://components/mobility/gearbox.usda@</Gearbox>
        )
        {
            double3 xformOp:translate = (-0.055, -0.2, 0.6)
            double3 xformOp:rotateXYZ = (0.0, 90.0, 0.0)
            uniform token[] xformOpOrder = ["xformOp:translate", "xformOp:rotateXYZ"]
            float inputs:torque.connect = </RockerBogie/BogieL/Motor_RL.outputs:torque>
        }
    }

    # ── Right bogie ─────────────────────────────────────────────────────────
    def Xform "BogieR" (
        prepend apiSchemas = ["PhysicsRigidBodyAPI", "PhysxRigidBodyAPI", "PhysicsMassAPI"]
    )
    {
        # The shorter, lighter member of the pair — and, like the rocker, kept heavy
        # on purpose. See RockerL for what lightening it did to the differential.
        float physics:mass = 30.0
        float3 physics:diagonalInertia = (15.0, 15.0, 1.5)
        double3 xformOp:translate = (0.9, -0.4, 0.6)
        uniform token[] xformOpOrder = ["xformOp:translate"]

        def Cylinder "FrontLink"
        {
            uniform token axis = "Z"
            double radius = 0.05
            double height = 0.447
            double3 xformOp:translate = (0.0, -0.1, -0.2)
            double3 xformOp:rotateXYZ = (-26.57, 0.0, 0.0)
            uniform token[] xformOpOrder = ["xformOp:translate", "xformOp:rotateXYZ"]
            color3f[] primvars:displayColor = [(0.45, 0.45, 0.48)]
            bool physics:collisionEnabled = false
        }

        def Cylinder "RearLink"
        {
            uniform token axis = "Z"
            double radius = 0.05
            double height = 0.632
            double3 xformOp:translate = (0.0, -0.1, 0.3)
            double3 xformOp:rotateXYZ = (18.43, 0.0, 0.0)
            uniform token[] xformOpOrder = ["xformOp:translate", "xformOp:rotateXYZ"]
            color3f[] primvars:displayColor = [(0.45, 0.45, 0.48)]
            bool physics:collisionEnabled = false
        }

        def Cylinder "MiddleAxle"
        {
            uniform token axis = "X"
            double radius = 0.035
            double height = 0.25
            double3 xformOp:translate = (0.125, -0.2, -0.4)
            uniform token[] xformOpOrder = ["xformOp:translate"]
            color3f[] primvars:displayColor = [(0.6, 0.6, 0.6)]
            bool physics:collisionEnabled = false
        }

        def Cylinder "RearAxle"
        {
            uniform token axis = "X"
            double radius = 0.035
            double height = 0.25
            double3 xformOp:translate = (0.125, -0.2, 0.6)
            uniform token[] xformOpOrder = ["xformOp:translate"]
            color3f[] primvars:displayColor = [(0.6, 0.6, 0.6)]
            bool physics:collisionEnabled = false
        }

        def Cylinder "JointCover"
        {
            uniform token axis = "X"
            double radius = 0.1
            double height = 0.1
            double3 xformOp:translate = (0.0, 0.0, 0.0)
            uniform token[] xformOpOrder = ["xformOp:translate"]
            color3f[] primvars:displayColor = [(0.85, 0.7, 0.2)]
            bool physics:collisionEnabled = false
        }

        # Simplified box collider (collision-only, hidden — see RockerL/Collider).
        def Cube "Collider" (
            prepend apiSchemas = ["PhysicsCollisionAPI"]
        )
        {
            double size = 1.0
            double3 xformOp:scale = (0.1, 0.1, 1.2)
            double3 xformOp:translate = (0.0, -0.1, 0.1)
            uniform token[] xformOpOrder = ["xformOp:translate", "xformOp:scale"]
            token visibility = "invisible"
            bool physics:collisionEnabled = true
        }

        # Middle Right Wheel
        def Cylinder "Wheel_MR" (
            prepend references = [
                @lunco://components/mobility/wheel.usda@</Wheel>,
                @lunco://components/mobility/suspensions/rocker.usda@</Suspension>,
            ]
        )
        {
            uniform token axis = "X"
            double radius = 0.4
            double height = 0.4
            float physxVehicleWheel:radius = 0.4
            float physics:mass = 12.0
            double3 xformOp:translate = (0.3, -0.2, -0.4)
            uniform token[] xformOpOrder = ["xformOp:translate"]
            color3f[] primvars:displayColor = [(0.15, 0.15, 0.15)]

            int lunco:wheel:index = 3
        }

        # Rear Right Wheel
        def Cylinder "Wheel_RR" (
            prepend references = [
                @lunco://components/mobility/wheel.usda@</Wheel>,
                @lunco://components/mobility/suspensions/rocker.usda@</Suspension>,
            ]
        )
        {
            uniform token axis = "X"
            double radius = 0.4
            double height = 0.4
            float physxVehicleWheel:radius = 0.4
            float physics:mass = 12.0
            double3 xformOp:translate = (0.3, -0.2, 0.6)
            uniform token[] xformOpOrder = ["xformOp:translate"]
            color3f[] primvars:displayColor = [(0.15, 0.15, 0.15)]

            int lunco:wheel:index = 5
        }

        # Indices 3 and 5, both odd ⇒ `drive_right`. Mirror of the left bogie.
        def Xform "Motor_MR" (
            prepend references = @lunco://components/mobility/motor.usda@</Motor>
        )
        {
            # On the axle, arm between motor and gearbox, turned onto X. See Motor_FL.
            double3 xformOp:translate = (-0.1, -0.2, -0.4)
            double3 xformOp:rotateXYZ = (0.0, 90.0, 0.0)
            uniform token[] xformOpOrder = ["xformOp:translate", "xformOp:rotateXYZ"]
            prepend rel lunco:motor:drivenWheel = </RockerBogie/BogieR/Wheel_MR>
            float inputs:demand.connect = </RockerBogie.outputs:drive_right>
            float lunco:motor:noLoadSpeed = 14400.0   # 12.9 km/h — see Motor_FL
        }

        def Xform "Gearbox_MR" (
            prepend references = @lunco://components/mobility/gearbox.usda@</Gearbox>
        )
        {
            double3 xformOp:translate = (0.055, -0.2, -0.4)
            double3 xformOp:rotateXYZ = (0.0, 90.0, 0.0)
            uniform token[] xformOpOrder = ["xformOp:translate", "xformOp:rotateXYZ"]
            float inputs:torque.connect = </RockerBogie/BogieR/Motor_MR.outputs:torque>
        }

        def Xform "Motor_RR" (
            prepend references = @lunco://components/mobility/motor.usda@</Motor>
        )
        {
            # On the axle, arm between motor and gearbox, turned onto X. See Motor_FL.
            double3 xformOp:translate = (-0.1, -0.2, 0.6)
            double3 xformOp:rotateXYZ = (0.0, 90.0, 0.0)
            uniform token[] xformOpOrder = ["xformOp:translate", "xformOp:rotateXYZ"]
            prepend rel lunco:motor:drivenWheel = </RockerBogie/BogieR/Wheel_RR>
            float inputs:demand.connect = </RockerBogie.outputs:drive_right>
            float lunco:motor:noLoadSpeed = 14400.0   # 12.9 km/h — see Motor_FL
        }

        def Xform "Gearbox_RR" (
            prepend references = @lunco://components/mobility/gearbox.usda@</Gearbox>
        )
        {
            double3 xformOp:translate = (0.055, -0.2, 0.6)
            double3 xformOp:rotateXYZ = (0.0, 90.0, 0.0)
            uniform token[] xformOpOrder = ["xformOp:translate", "xformOp:rotateXYZ"]
            float inputs:torque.connect = </RockerBogie/BogieR/Motor_RR.outputs:torque>
        }
    }

    # All joints below DELIBERATELY omit `physics:localPos0`/`localPos1`: each body's
    # placement is already its `xformOp:translate`, and the avian joint reader DERIVES
    # the anchor from the composed world poses (body1's origin in body0's rotation
    # frame; anchor on body1 = origin). This works for the sibling rocker↔bogie hinges
    # and the scaled hierarchy, so no anchor is typed — or left to drift — twice.
    # Author a `localPos0` on a joint to override the derivation.
    #
    # ── Lateral-axis revolute hinges (chassis ↔ rocker) ─────────────────────
    # HingeL/R: chassis <-> rocker joints.
    # NASA MER/MSL use mechanical stops limiting rocker travel to +/-30 to +/-45 degrees.
    # We use +/-30 degrees to keep the chassis level and prevent differential lockup.
    def PhysicsRevoluteJoint "HingeL" (
        doc = "Chassis-to-rocker hinge. Limited to +/-30 deg to match NASA mechanical stops, preventing excessive chassis roll and differential lockup."
    )
    {
        rel physics:body0 = </RockerBogie>
        rel physics:body1 = </RockerBogie/RockerL>
        uniform token physics:axis = "X"
        float physics:lowerLimit = -30
        float physics:upperLimit = 30
    }
    def PhysicsRevoluteJoint "HingeR" (
        doc = "Chassis-to-rocker hinge. Limited to +/-30 deg to match NASA mechanical stops, preventing excessive chassis roll and differential lockup."
    )
    {
        rel physics:body0 = </RockerBogie>
        rel physics:body1 = </RockerBogie/RockerR>
        uniform token physics:axis = "X"
        float physics:lowerLimit = -30
        float physics:upperLimit = 30
    }

    # ── Differential coupling (rocker-bogie holonomic constraint) ───────────
    # The standard PhysX gear joint over the two chassis↔rocker hinges: it softly
    # couples θ_left + θ_right → restSum (the drive's targetPosition), so the chassis
    # pitch tracks the rocker average instead of flopping on a free pitch DOF. A rigid
    # gear would fight the terrain and chatter, so the compliance is the joint's own
    # angular PhysicsDriveAPI (a strong spring-damper), not an ideal constraint.
    #   stiffness — how strongly the rockers mirror each other
    #   damping   — kills differential oscillation
    #   targetPosition — symmetric rest sum (0 rad)
    #
    # ⚠ SOLVED IMPLICITLY. THIS IS NO LONGER A STABILITY KNOB — BUT IT IS NOT YET
    #   AN IDEAL GEAR EITHER. Read both halves before changing it.
    #
    # `differential_coupling_system` now evaluates the coupling with backward Euler
    # against the constraint's own inverse inertia (`J·M⁻¹·Jᵀ`), so the solved
    # torque is bounded by what the step can absorb. Two things follow, both
    # measured on `scenes/tests/rocker_bogie.usda` (2026-07-22):
    #
    #   · NO STIFFNESS DIVERGES ANY MORE. The old EXPLICIT penalty (`λ = k·c + d·ċ`)
    #     went to NaN inside 10 s at 30 000 and at 60 000. Nothing does now — the
    #     value below is 6× the old NaN threshold and the rig is steady.
    #   · MASS NO LONGER SOFTENS IT. `w` scales the response with the inertia it
    #     acts on. Under the explicit form a 400 kg hull sagged the mirroring to a
    #     29% residual (a FAILING mechanism); it is 8.6% now. At the shipped 300 kg
    #     the residual went 20% → 13.4%, back inside the test's original 15% bound.
    #
    # ⚠ BUT DO NOT SIMPLY CRANK IT. This is still an EXTERNAL torque applied
    # alongside avian's solver, not a constraint solved WITH it, so pushing toward
    # the holonomic limit makes the coupling shove the vehicle around rather than
    # merely couple it: at 1e6 the gear cancels perfectly (L+R = 0.000) and walks
    # the rover clean off the test step by t ≈ 4 s; at 1e8 the rig tumbles (168° of
    # roll). 1e5 is the measured knee — the stiffest setting that still leaves the
    # rover sitting where it was put.
    #
    # A real rocker-bogie differential is a bar or a bevel gearset, with no
    # compliance at all. Reaching that honestly means solving this INSIDE the
    # substep loop with the hinges, as a real constraint. Until then this is a very
    # stiff, mass-independent, unconditionally stable spring — which is a different
    # and much better thing than what it was, but still a spring.
    def PhysxPhysicsGearJoint "Differential" (
        prepend apiSchemas = ["PhysicsDriveAPI:angular"]
    )
    {
        rel physxGearJoint:hinge0 = </RockerBogie/HingeL>
        rel physxGearJoint:hinge1 = </RockerBogie/HingeR>
        float physxGearJoint:gearRatio = -1.0
        float drive:angular:physics:targetPosition = 0.0
        float drive:angular:physics:stiffness = 100000.0
        float drive:angular:physics:damping = 5000.0
    }

    # ── Lateral-axis revolute hinges (rocker ↔ bogie) ───────────────────────
    # BogieHingeL/R: rocker <-> bogie joints.
    # NASA rovers limit bogie rotation to +/-20 to +/-30 degrees to prevent the
    # middle/rear wheels from colliding with the rocker frame or chassis belly.
    # We use +/-20 degrees as a safe operating envelope.
    def PhysicsRevoluteJoint "BogieHingeL" (
        doc = "Rocker-to-bogie hinge. Limited to +/-20 deg to match NASA stops, preventing middle/rear wheels from colliding with the rocker frame."
    )
    {
        rel physics:body0 = </RockerBogie/RockerL>
        rel physics:body1 = </RockerBogie/BogieL>
        uniform token physics:axis = "X"
        float physics:lowerLimit = -20
        float physics:upperLimit = 20
    }
    def PhysicsRevoluteJoint "BogieHingeR" (
        doc = "Rocker-to-bogie hinge. Limited to +/-20 deg to match NASA stops, preventing middle/rear wheels from colliding with the rocker frame."
    )
    {
        rel physics:body0 = </RockerBogie/RockerR>
        rel physics:body1 = </RockerBogie/BogieR>
        uniform token physics:axis = "X"
        float physics:lowerLimit = -20
        float physics:upperLimit = 20
    }

    # ── Wheel revolute joints (rocker/bogie ↔ wheel) ────────────────────────
    # The joint is the motor's OUTPUT COUPLING, not the motor: it carries
    # `PhysicsDriveAPI:angular`, the drive `type` and the axis, and NOTHING ELSE.
    # `maxForce` and `targetVelocity` are deliberately absent — the loader writes
    # them from the `Motor_*` / `Gearbox_*` pair that names this joint's WHEEL via
    # `lunco:motor:drivenWheel` — the loader follows wheel → joint to get here — so the
    # torque ceiling is stated once, on the part that makes the torque, instead of being
    # typed here as a second opinion.
    def PhysicsRevoluteJoint "Wheel_FL_Hinge" (
        prepend apiSchemas = ["PhysicsDriveAPI:angular"]
    )
    {
        rel physics:body0 = </RockerBogie/RockerL>
        rel physics:body1 = </RockerBogie/RockerL/Wheel_FL>
        uniform token physics:axis = "X"
        uniform token drive:angular:physics:type = "force"
    }

    def PhysicsRevoluteJoint "Wheel_FR_Hinge" (
        prepend apiSchemas = ["PhysicsDriveAPI:angular"]
    )
    {
        rel physics:body0 = </RockerBogie/RockerR>
        rel physics:body1 = </RockerBogie/RockerR/Wheel_FR>
        uniform token physics:axis = "X"
        uniform token drive:angular:physics:type = "force"
    }

    def PhysicsRevoluteJoint "Wheel_ML_Hinge" (
        prepend apiSchemas = ["PhysicsDriveAPI:angular"]
    )
    {
        rel physics:body0 = </RockerBogie/BogieL>
        rel physics:body1 = </RockerBogie/BogieL/Wheel_ML>
        uniform token physics:axis = "X"
        uniform token drive:angular:physics:type = "force"
    }

    def PhysicsRevoluteJoint "Wheel_MR_Hinge" (
        prepend apiSchemas = ["PhysicsDriveAPI:angular"]
    )
    {
        rel physics:body0 = </RockerBogie/BogieR>
        rel physics:body1 = </RockerBogie/BogieR/Wheel_MR>
        uniform token physics:axis = "X"
        uniform token drive:angular:physics:type = "force"
    }

    def PhysicsRevoluteJoint "Wheel_RL_Hinge" (
        prepend apiSchemas = ["PhysicsDriveAPI:angular"]
    )
    {
        rel physics:body0 = </RockerBogie/BogieL>
        rel physics:body1 = </RockerBogie/BogieL/Wheel_RL>
        uniform token physics:axis = "X"
        uniform token drive:angular:physics:type = "force"
    }

    def PhysicsRevoluteJoint "Wheel_RR_Hinge" (
        prepend apiSchemas = ["PhysicsDriveAPI:angular"]
    )
    {
        rel physics:body0 = </RockerBogie/BogieR>
        rel physics:body1 = </RockerBogie/BogieR/Wheel_RR>
        uniform token physics:axis = "X"
        uniform token drive:angular:physics:type = "force"
    }

    # --- Drive law -----------------------------------------------------------
    # HOW throttle/steer become per-side drive is COMPOSITION, not an
    # enumeration. The plain authored state is the instant built-in skid kernel
    # (`PhysxVehicleTankDifferentialAPI` above). For a solver-clocked per-side
    # motor lag, compose on the SAME skid law the other skid rovers use:
    #
    #   def "Rover" (
    #       prepend references = [
    #           @lunco://vessels/rovers/rocker_bogie.usda@</RockerBogie>,
    #           @lunco://components/mobility/drive_laws/modelica_skid.usda@</DriveLaw>,
    #       ]
    #   ) {}
    #
    # The wheels here author no `inputs:drive` connection, so they use the index-parity
    # default (even 0/2/4 = FL/ML/RL ⇒ drive_left, odd 1/3/5 = FR/MR/RR ⇒
    # drive_right) — exactly the port pair the skid law writes.

    # --- Power: does driving cost anything ----------------------------------
    # ORTHOGONAL to the drive law: `infinite` is EMPTY — the absence of a battery
    # is today's drive-forever behavior. `battery` composes the RoverBattery.mo
    # energy budget onto the root: drain follows the commanded drive magnitude,
    # and its `alive` cutoff brownouts the drive ports over the last ~2% of
    # charge — a variant chooses a component, it never restates one.
    #
    # Same two sets `six_wheel_rover.usda` carries, because the difficulty tiers
    # (`variants/rover_*.usda`) sit on THIS chassis now and a tier must not lose a
    # capability by changing suspension.
    variantSet "power" = {
        "infinite" {
        }

        "battery" (
            prepend references = @lunco://components/power/rover_battery.usda@</Power>
        ) {
        }
    }

    # --- Thermal: do the motors have temperatures ---------------------------
    # `none` is EMPTY. `basic` composes the RoverMotorThermal.mo per-side heat
    # balance onto the root: pure telemetry (`temp_left`/`temp_right`, kelvin,
    # readable/watchable ports), nothing acts on it — same choose-a-component
    # shape as `power`.
    variantSet "thermal" = {
        "none" {
        }

        "basic" (
            prepend references = @lunco://components/thermal/motor_thermal.usda@</Thermal>
        ) {
        }
    }
}
