#usda 1.0
(
    defaultPrim = "RockerBogie"
    upAxis = "Y"
    metersPerUnit = 1
)

# G5 — rocker-bogie chassis with a differential coupling.
#
# A complete physical joint-based rocker-bogie suspension with 6 motorized wheels:
#   - Two side rockers (RockerL/R) hinge to the chassis on the X axis.
#   - Two bogies (BogieL/R) hinge to the rear of the rockers on the X axis.
#   - Six wheels (FL/FR/ML/MR/RL/RR) reference the reusable motorized wheel components.
#   - The differential coupling softly enforces: θ_left + θ_right → 0.
#   - Controllable via keyboard/UI through PhysxVehicleTankDifferentialAPI.
#
# FOR PARAMETER EDITING GUIDE: See the accompanying README.md in this directory.

def Xform "RockerBogie" (
    # An ASSEMBLY: a model built out of other models. Its wheels are component models
    # that arrive by reference, and USD forbids a `component` from containing them.
    kind = "assembly"
    prepend apiSchemas = [
        "PhysicsRigidBodyAPI", "PhysxRigidBodyAPI",
        "PhysicsMassAPI",
        "PhysicsArticulationRootAPI",
        "PhysxVehicleContextAPI",
        "PhysxVehicleTankDifferentialAPI", "LunCoCatalogAPI"
    ]
    # The ON-BOARD COMPUTER, as a second reference arc — the rover's COMMAND
    # SURFACE (`throttle`/`steer`/`brake`). Ships with the chassis; without one
    # this rover accepts no commands at all. See `skid_rover.usda`.
    prepend references = @lunco://components/avionics/obc.usda@</OBC>
)
{
    uniform bool lunco:spawnable = true
    # --- VEHICLE MASS & DAMPING ---
    # Edit the chassis mass here (default 300 kg)
    float physics:mass = 300.0
    float lunco:spawnLift = 1.5
    float physxRigidBody:linearDamping = 0.4
    float physxRigidBody:angularDamping = 2.0

    # Intent->port control (stage 2): shared rover profile as a child `references`
    # arc so it composes through a spawn/reference like the wheels.
    def "Controls" (
        prepend references = @lunco://vessels/control_profiles.usda@</RoverControls>
    )
    {
    }

    # --- CHASSIS GEOMETRY & VISUALS ---
    # Main body — the shared box chassis component (collider + panelised hull
    # material), referenced INTO this prim so the name `Body` and every local
    # opinion below survive. Its own scale wins over the component default.
    def Cube "Body" (
        prepend references = @lunco://components/mobility/chassis/box_chassis.usda@</Chassis>
    )
    {
        double3 xformOp:scale = (1.2, 0.4, 1.8)
        # NASA-ish white-grey — the science-platform archetype. Colour is
        # `primvars:displayColor` and nothing else; the hull shader consumes it
        # as the base paint.
        color3f[] primvars:displayColor = [(0.9, 0.9, 0.88)]
        # Gold accent, keeping the solar-foil heritage of the original body.
        over "HullLook"
        {
            over "Shader"
            {
                color3f inputs:accent_color = (0.85, 0.7, 0.2)
            }
        }
    }

    # Slanted Solar panel deck on top of the chassis
    def Cube "SolarDeck"
    {
        double size = 1.0
        double3 xformOp:translate = (0.0, 0.21, 0.0)
        double3 xformOp:scale = (1.3, 0.02, 1.9)
        uniform token[] xformOpOrder = ["xformOp:translate", "xformOp:scale"]
        color3f[] primvars:displayColor = [(0.05, 0.05, 0.2)]
        bool physics:collisionEnabled = false
    }

    # High-gain antenna mast and dish
    def Cylinder "AntennaMast"
    {
        uniform token axis = "Y"
        double radius = 0.015
        double height = 0.3
        double3 xformOp:translate = (0.3, 0.35, 0.6)
        uniform token[] xformOpOrder = ["xformOp:translate"]
        color3f[] primvars:displayColor = [(0.6, 0.6, 0.6)]
        bool physics:collisionEnabled = false
    }

    def Cylinder "AntennaDish"
    {
        uniform token axis = "Y"
        double radius = 0.15
        double height = 0.02
        double3 xformOp:translate = (0.3, 0.5, 0.6)
        double3 xformOp:rotateXYZ = (30.0, 45.0, 0.0)
        uniform token[] xformOpOrder = ["xformOp:translate", "xformOp:rotateXYZ"]
        color3f[] primvars:displayColor = [(0.8, 0.8, 0.8)]
        bool physics:collisionEnabled = false
    }

    # Instrument platform / science mast
    def Cylinder "Mast"
    {
        uniform token axis = "Y"
        double radius = 0.04
        double height = 0.8
        double3 xformOp:translate = (0.0, 0.5, -0.6)
        uniform token[] xformOpOrder = ["xformOp:translate"]
        color3f[] primvars:displayColor = [(0.6, 0.6, 0.6)]
        bool physics:collisionEnabled = false
    }

    def Cube "CameraHead"
    {
        double size = 1.0
        double3 xformOp:scale = (0.2, 0.15, 0.15)
        double3 xformOp:translate = (0.0, 0.95, -0.6)
        uniform token[] xformOpOrder = ["xformOp:translate", "xformOp:scale"]
        color3f[] primvars:displayColor = [(0.15, 0.15, 0.15)]
        bool physics:collisionEnabled = false
    }

    # Headlights
    def Xform "Headlight_L" (
        prepend references = @lunco://components/lights/headlight.usda@</Headlight>
    )
    {
        double3 xformOp:translate = (-0.5, 0.1, -0.9)
        double3 xformOp:rotateXYZ = (-15, 0, 0)
        uniform token[] xformOpOrder = ["xformOp:translate", "xformOp:rotateXYZ"]
    }

    def Xform "Headlight_R" (
        prepend references = @lunco://components/lights/headlight.usda@</Headlight>
    )
    {
        double3 xformOp:translate = (0.5, 0.1, -0.9)
        double3 xformOp:rotateXYZ = (-15, 0, 0)
        uniform token[] xformOpOrder = ["xformOp:translate", "xformOp:rotateXYZ"]
    }

    # ── Left rocker ─────────────────────────────────────────────────────────
    def Xform "RockerL" (
        prepend apiSchemas = ["PhysicsRigidBodyAPI", "PhysxRigidBodyAPI", "PhysicsMassAPI"]
    )
    {
        float physics:mass = 50.0
        float3 physics:diagonalInertia = (30.0, 30.0, 3.0)
        double3 xformOp:translate = (-0.9, -0.2, 0.0)
        uniform token[] xformOpOrder = ["xformOp:translate"]

        # Rocker main forward-down link (pivots down/forward to front wheel)
        # Length: 1.265m, Midpoint: (0.0, -0.2, -0.6), Rotated: -18.43 deg about X
        def Cylinder "FrontLink"
        {
            uniform token axis = "Z"
            double radius = 0.06
            double height = 1.265
            double3 xformOp:translate = (0.0, -0.2, -0.6)
            double3 xformOp:rotateXYZ = (-18.43, 0.0, 0.0)
            uniform token[] xformOpOrder = ["xformOp:translate", "xformOp:rotateXYZ"]
            color3f[] primvars:displayColor = [(0.35, 0.35, 0.38)]
            bool physics:collisionEnabled = false
        }

        # Rocker rear-down link (pivots down/backward to bogie hinge)
        # Length: 0.632m, Midpoint: (0.0, -0.1, 0.3), Rotated: 18.43 deg about X
        def Cylinder "RearLink"
        {
            uniform token axis = "Z"
            double radius = 0.06
            double height = 0.632
            double3 xformOp:translate = (0.0, -0.1, 0.3)
            double3 xformOp:rotateXYZ = (18.43, 0.0, 0.0)
            uniform token[] xformOpOrder = ["xformOp:translate", "xformOp:rotateXYZ"]
            color3f[] primvars:displayColor = [(0.35, 0.35, 0.38)]
            bool physics:collisionEnabled = false
        }

        # Outward X-axis axle to front wheel
        def Cylinder "Axle"
        {
            uniform token axis = "X"
            double radius = 0.04
            double height = 0.25
            double3 xformOp:translate = (-0.125, -0.4, -1.2)
            uniform token[] xformOpOrder = ["xformOp:translate"]
            color3f[] primvars:displayColor = [(0.6, 0.6, 0.6)]
            bool physics:collisionEnabled = false
        }

        # Rocker joint cover housing
        def Cylinder "JointCover"
        {
            uniform token axis = "X"
            double radius = 0.12
            double height = 0.12
            double3 xformOp:translate = (0.0, 0.0, 0.0)
            uniform token[] xformOpOrder = ["xformOp:translate"]
            color3f[] primvars:displayColor = [(0.85, 0.7, 0.2)]
            bool physics:collisionEnabled = false
        }

        # Simplified box collider for the rocker arm (clears the bogie space).
        # `visibility = "invisible"` — collision-only: the loader would otherwise
        # render this as a white bar (no displayColor → Color::WHITE fallback).
        def Cube "Collider" (
            prepend apiSchemas = ["PhysicsCollisionAPI"]
        )
        {
            double size = 1.0
            double3 xformOp:scale = (0.12, 0.12, 1.2)
            double3 xformOp:translate = (0.0, -0.2, -0.6)
            uniform token[] xformOpOrder = ["xformOp:translate", "xformOp:scale"]
            token visibility = "invisible"
            bool physics:collisionEnabled = true
        }

        # Front Left Wheel
        def Cylinder "Wheel_FL" (
            prepend references = [
                @lunco://components/mobility/wheel.usda@</Wheel>,
                @lunco://components/mobility/suspensions/rocker.usda@</Suspension>,
            ]
        )
        {
            uniform token axis = "X"
            double radius = 0.4
            double height = 0.3
            double3 xformOp:translate = (-0.25, -0.4, -1.2)
            uniform token[] xformOpOrder = ["xformOp:translate"]
            color3f[] primvars:displayColor = [(0.15, 0.15, 0.15)]

            # --- WHEEL DYNAMICS CONFIGURATION ---
            int lunco:wheel:index = 0
        }

        # Motor + reduction for the front-left wheel. A CHILD OF THE ROCKER, not of
        # the chassis: the rocker is its own rigid body, and a motor bolted to the
        # arm must swing with the arm. Placed inboard of the wheel so its housing
        # never overlaps the wheel collider.
        #
        #   τ_axle = stallTorque · (1 − ω_shaft/noLoadSpeed) · ratio · efficiency · demand
        # clamped at the gearbox's `maxOutputTorque`; axle no-load speed =
        # 14400/1200 = 12 rad/s. Wheel index 0 is even ⇒ `drive_left`, the same
        # index-parity channel the wheel itself binds.
        def Xform "Motor_FL" (
            prepend references = @lunco://components/mobility/motor.usda@</Motor>
        )
        {
            double3 xformOp:translate = (0.3, -0.4, -1.2)
            uniform token[] xformOpOrder = ["xformOp:translate"]
            prepend rel lunco:motor:drivenWheel = </RockerBogie/RockerL/Wheel_FL>
            float inputs:demand.connect = </RockerBogie.outputs:drive_left>
        }

        def Xform "Gearbox_FL" (
            prepend references = @lunco://components/mobility/gearbox.usda@</Gearbox>
        )
        {
            double3 xformOp:translate = (0.15, -0.4, -1.2)
            uniform token[] xformOpOrder = ["xformOp:translate"]
            float inputs:torque.connect = </RockerBogie/RockerL/Motor_FL.outputs:torque>
        }
    }

    # ── Right rocker ────────────────────────────────────────────────────────
    def Xform "RockerR" (
        prepend apiSchemas = ["PhysicsRigidBodyAPI", "PhysxRigidBodyAPI", "PhysicsMassAPI"]
    )
    {
        float physics:mass = 50.0
        float3 physics:diagonalInertia = (30.0, 30.0, 3.0)
        double3 xformOp:translate = (0.9, -0.2, 0.0)
        uniform token[] xformOpOrder = ["xformOp:translate"]

        def Cylinder "FrontLink"
        {
            uniform token axis = "Z"
            double radius = 0.06
            double height = 1.265
            double3 xformOp:translate = (0.0, -0.2, -0.6)
            double3 xformOp:rotateXYZ = (-18.43, 0.0, 0.0)
            uniform token[] xformOpOrder = ["xformOp:translate", "xformOp:rotateXYZ"]
            color3f[] primvars:displayColor = [(0.35, 0.35, 0.38)]
            bool physics:collisionEnabled = false
        }

        def Cylinder "RearLink"
        {
            uniform token axis = "Z"
            double radius = 0.06
            double height = 0.632
            double3 xformOp:translate = (0.0, -0.1, 0.3)
            double3 xformOp:rotateXYZ = (18.43, 0.0, 0.0)
            uniform token[] xformOpOrder = ["xformOp:translate", "xformOp:rotateXYZ"]
            color3f[] primvars:displayColor = [(0.35, 0.35, 0.38)]
            bool physics:collisionEnabled = false
        }

        def Cylinder "Axle"
        {
            uniform token axis = "X"
            double radius = 0.04
            double height = 0.25
            double3 xformOp:translate = (0.125, -0.4, -1.2)
            uniform token[] xformOpOrder = ["xformOp:translate"]
            color3f[] primvars:displayColor = [(0.6, 0.6, 0.6)]
            bool physics:collisionEnabled = false
        }

        def Cylinder "JointCover"
        {
            uniform token axis = "X"
            double radius = 0.12
            double height = 0.12
            double3 xformOp:translate = (0.0, 0.0, 0.0)
            uniform token[] xformOpOrder = ["xformOp:translate"]
            color3f[] primvars:displayColor = [(0.85, 0.7, 0.2)]
            bool physics:collisionEnabled = false
        }

        # Simplified box collider for the rocker arm (clears the bogie space).
        # `visibility = "invisible"` — collision-only: the loader would otherwise
        # render this as a white bar (no displayColor → Color::WHITE fallback).
        def Cube "Collider" (
            prepend apiSchemas = ["PhysicsCollisionAPI"]
        )
        {
            double size = 1.0
            double3 xformOp:scale = (0.12, 0.12, 1.2)
            double3 xformOp:translate = (0.0, -0.2, -0.6)
            uniform token[] xformOpOrder = ["xformOp:translate", "xformOp:scale"]
            token visibility = "invisible"
            bool physics:collisionEnabled = true
        }

        # Front Right Wheel
        def Cylinder "Wheel_FR" (
            prepend references = [
                @lunco://components/mobility/wheel.usda@</Wheel>,
                @lunco://components/mobility/suspensions/rocker.usda@</Suspension>,
            ]
        )
        {
            uniform token axis = "X"
            double radius = 0.4
            double height = 0.3
            double3 xformOp:translate = (0.25, -0.4, -1.2)
            uniform token[] xformOpOrder = ["xformOp:translate"]
            color3f[] primvars:displayColor = [(0.15, 0.15, 0.15)]

            int lunco:wheel:index = 1
        }

        # Wheel index 1 is odd ⇒ `drive_right`. Mirror of the left rocker.
        def Xform "Motor_FR" (
            prepend references = @lunco://components/mobility/motor.usda@</Motor>
        )
        {
            double3 xformOp:translate = (-0.3, -0.4, -1.2)
            uniform token[] xformOpOrder = ["xformOp:translate"]
            prepend rel lunco:motor:drivenWheel = </RockerBogie/RockerR/Wheel_FR>
            float inputs:demand.connect = </RockerBogie.outputs:drive_right>
        }

        def Xform "Gearbox_FR" (
            prepend references = @lunco://components/mobility/gearbox.usda@</Gearbox>
        )
        {
            double3 xformOp:translate = (-0.15, -0.4, -1.2)
            uniform token[] xformOpOrder = ["xformOp:translate"]
            float inputs:torque.connect = </RockerBogie/RockerR/Motor_FR.outputs:torque>
        }
    }

    # ── Left bogie ──────────────────────────────────────────────────────────
    def Xform "BogieL" (
        prepend apiSchemas = ["PhysicsRigidBodyAPI", "PhysxRigidBodyAPI", "PhysicsMassAPI"]
    )
    {
        float physics:mass = 30.0
        float3 physics:diagonalInertia = (15.0, 15.0, 1.5)
        double3 xformOp:translate = (-0.9, -0.4, 0.6)
        uniform token[] xformOpOrder = ["xformOp:translate"]

        # Bogie front-down link (goes down/forward to middle wheel)
        # Length: 0.447m, Midpoint: (0.0, -0.1, -0.2), Rotated: -26.57 deg about X
        def Cylinder "FrontLink"
        {
            uniform token axis = "Z"
            double radius = 0.05
            double height = 0.447
            double3 xformOp:translate = (0.0, -0.1, -0.2)
            double3 xformOp:rotateXYZ = (-26.57, 0.0, 0.0)
            uniform token[] xformOpOrder = ["xformOp:translate", "xformOp:rotateXYZ"]
            color3f[] primvars:displayColor = [(0.45, 0.45, 0.48)]
            bool physics:collisionEnabled = false
        }

        # Bogie rear-down link (goes down/backward to rear wheel)
        # Length: 0.632m, Midpoint: (0.0, -0.1, 0.3), Rotated: 18.43 deg about X
        def Cylinder "RearLink"
        {
            uniform token axis = "Z"
            double radius = 0.05
            double height = 0.632
            double3 xformOp:translate = (0.0, -0.1, 0.3)
            double3 xformOp:rotateXYZ = (18.43, 0.0, 0.0)
            uniform token[] xformOpOrder = ["xformOp:translate", "xformOp:rotateXYZ"]
            color3f[] primvars:displayColor = [(0.45, 0.45, 0.48)]
            bool physics:collisionEnabled = false
        }

        # Axle to middle wheel
        def Cylinder "MiddleAxle"
        {
            uniform token axis = "X"
            double radius = 0.035
            double height = 0.25
            double3 xformOp:translate = (-0.125, -0.2, -0.4)
            uniform token[] xformOpOrder = ["xformOp:translate"]
            color3f[] primvars:displayColor = [(0.6, 0.6, 0.6)]
            bool physics:collisionEnabled = false
        }

        # Axle to rear wheel
        def Cylinder "RearAxle"
        {
            uniform token axis = "X"
            double radius = 0.035
            double height = 0.25
            double3 xformOp:translate = (-0.125, -0.2, 0.6)
            uniform token[] xformOpOrder = ["xformOp:translate"]
            color3f[] primvars:displayColor = [(0.6, 0.6, 0.6)]
            bool physics:collisionEnabled = false
        }

        # Joint cover housing
        def Cylinder "JointCover"
        {
            uniform token axis = "X"
            double radius = 0.1
            double height = 0.1
            double3 xformOp:translate = (0.0, 0.0, 0.0)
            uniform token[] xformOpOrder = ["xformOp:translate"]
            color3f[] primvars:displayColor = [(0.85, 0.7, 0.2)]
            bool physics:collisionEnabled = false
        }

        # Simplified box collider (collision-only, hidden — see RockerL/Collider).
        def Cube "Collider" (
            prepend apiSchemas = ["PhysicsCollisionAPI"]
        )
        {
            double size = 1.0
            double3 xformOp:scale = (0.1, 0.1, 1.2)
            double3 xformOp:translate = (0.0, -0.1, 0.1)
            uniform token[] xformOpOrder = ["xformOp:translate", "xformOp:scale"]
            token visibility = "invisible"
            bool physics:collisionEnabled = true
        }

        # Middle Left Wheel
        def Cylinder "Wheel_ML" (
            prepend references = [
                @lunco://components/mobility/wheel.usda@</Wheel>,
                @lunco://components/mobility/suspensions/rocker.usda@</Suspension>,
            ]
        )
        {
            uniform token axis = "X"
            double radius = 0.4
            double height = 0.3
            double3 xformOp:translate = (-0.25, -0.2, -0.4)
            uniform token[] xformOpOrder = ["xformOp:translate"]
            color3f[] primvars:displayColor = [(0.15, 0.15, 0.15)]

            int lunco:wheel:index = 2
        }

        # Rear Left Wheel
        def Cylinder "Wheel_RL" (
            prepend references = [
                @lunco://components/mobility/wheel.usda@</Wheel>,
                @lunco://components/mobility/suspensions/rocker.usda@</Suspension>,
            ]
        )
        {
            uniform token axis = "X"
            double radius = 0.4
            double height = 0.3
            double3 xformOp:translate = (-0.25, -0.2, 0.6)
            uniform token[] xformOpOrder = ["xformOp:translate"]
            color3f[] primvars:displayColor = [(0.15, 0.15, 0.15)]

            int lunco:wheel:index = 4
        }

        # Two motors on this bogie — indices 2 and 4, both even ⇒ `drive_left`.
        def Xform "Motor_ML" (
            prepend references = @lunco://components/mobility/motor.usda@</Motor>
        )
        {
            double3 xformOp:translate = (0.3, -0.2, -0.4)
            uniform token[] xformOpOrder = ["xformOp:translate"]
            prepend rel lunco:motor:drivenWheel = </RockerBogie/BogieL/Wheel_ML>
            float inputs:demand.connect = </RockerBogie.outputs:drive_left>
        }

        def Xform "Gearbox_ML" (
            prepend references = @lunco://components/mobility/gearbox.usda@</Gearbox>
        )
        {
            double3 xformOp:translate = (0.15, -0.2, -0.4)
            uniform token[] xformOpOrder = ["xformOp:translate"]
            float inputs:torque.connect = </RockerBogie/BogieL/Motor_ML.outputs:torque>
        }

        def Xform "Motor_RL" (
            prepend references = @lunco://components/mobility/motor.usda@</Motor>
        )
        {
            double3 xformOp:translate = (0.3, -0.2, 0.6)
            uniform token[] xformOpOrder = ["xformOp:translate"]
            prepend rel lunco:motor:drivenWheel = </RockerBogie/BogieL/Wheel_RL>
            float inputs:demand.connect = </RockerBogie.outputs:drive_left>
        }

        def Xform "Gearbox_RL" (
            prepend references = @lunco://components/mobility/gearbox.usda@</Gearbox>
        )
        {
            double3 xformOp:translate = (0.15, -0.2, 0.6)
            uniform token[] xformOpOrder = ["xformOp:translate"]
            float inputs:torque.connect = </RockerBogie/BogieL/Motor_RL.outputs:torque>
        }
    }

    # ── Right bogie ─────────────────────────────────────────────────────────
    def Xform "BogieR" (
        prepend apiSchemas = ["PhysicsRigidBodyAPI", "PhysxRigidBodyAPI", "PhysicsMassAPI"]
    )
    {
        float physics:mass = 30.0
        float3 physics:diagonalInertia = (15.0, 15.0, 1.5)
        double3 xformOp:translate = (0.9, -0.4, 0.6)
        uniform token[] xformOpOrder = ["xformOp:translate"]

        def Cylinder "FrontLink"
        {
            uniform token axis = "Z"
            double radius = 0.05
            double height = 0.447
            double3 xformOp:translate = (0.0, -0.1, -0.2)
            double3 xformOp:rotateXYZ = (-26.57, 0.0, 0.0)
            uniform token[] xformOpOrder = ["xformOp:translate", "xformOp:rotateXYZ"]
            color3f[] primvars:displayColor = [(0.45, 0.45, 0.48)]
            bool physics:collisionEnabled = false
        }

        def Cylinder "RearLink"
        {
            uniform token axis = "Z"
            double radius = 0.05
            double height = 0.632
            double3 xformOp:translate = (0.0, -0.1, 0.3)
            double3 xformOp:rotateXYZ = (18.43, 0.0, 0.0)
            uniform token[] xformOpOrder = ["xformOp:translate", "xformOp:rotateXYZ"]
            color3f[] primvars:displayColor = [(0.45, 0.45, 0.48)]
            bool physics:collisionEnabled = false
        }

        def Cylinder "MiddleAxle"
        {
            uniform token axis = "X"
            double radius = 0.035
            double height = 0.25
            double3 xformOp:translate = (0.125, -0.2, -0.4)
            uniform token[] xformOpOrder = ["xformOp:translate"]
            color3f[] primvars:displayColor = [(0.6, 0.6, 0.6)]
            bool physics:collisionEnabled = false
        }

        def Cylinder "RearAxle"
        {
            uniform token axis = "X"
            double radius = 0.035
            double height = 0.25
            double3 xformOp:translate = (0.125, -0.2, 0.6)
            uniform token[] xformOpOrder = ["xformOp:translate"]
            color3f[] primvars:displayColor = [(0.6, 0.6, 0.6)]
            bool physics:collisionEnabled = false
        }

        def Cylinder "JointCover"
        {
            uniform token axis = "X"
            double radius = 0.1
            double height = 0.1
            double3 xformOp:translate = (0.0, 0.0, 0.0)
            uniform token[] xformOpOrder = ["xformOp:translate"]
            color3f[] primvars:displayColor = [(0.85, 0.7, 0.2)]
            bool physics:collisionEnabled = false
        }

        # Simplified box collider (collision-only, hidden — see RockerL/Collider).
        def Cube "Collider" (
            prepend apiSchemas = ["PhysicsCollisionAPI"]
        )
        {
            double size = 1.0
            double3 xformOp:scale = (0.1, 0.1, 1.2)
            double3 xformOp:translate = (0.0, -0.1, 0.1)
            uniform token[] xformOpOrder = ["xformOp:translate", "xformOp:scale"]
            token visibility = "invisible"
            bool physics:collisionEnabled = true
        }

        # Middle Right Wheel
        def Cylinder "Wheel_MR" (
            prepend references = [
                @lunco://components/mobility/wheel.usda@</Wheel>,
                @lunco://components/mobility/suspensions/rocker.usda@</Suspension>,
            ]
        )
        {
            uniform token axis = "X"
            double radius = 0.4
            double height = 0.3
            double3 xformOp:translate = (0.25, -0.2, -0.4)
            uniform token[] xformOpOrder = ["xformOp:translate"]
            color3f[] primvars:displayColor = [(0.15, 0.15, 0.15)]

            int lunco:wheel:index = 3
        }

        # Rear Right Wheel
        def Cylinder "Wheel_RR" (
            prepend references = [
                @lunco://components/mobility/wheel.usda@</Wheel>,
                @lunco://components/mobility/suspensions/rocker.usda@</Suspension>,
            ]
        )
        {
            uniform token axis = "X"
            double radius = 0.4
            double height = 0.3
            double3 xformOp:translate = (0.25, -0.2, 0.6)
            uniform token[] xformOpOrder = ["xformOp:translate"]
            color3f[] primvars:displayColor = [(0.15, 0.15, 0.15)]

            int lunco:wheel:index = 5
        }

        # Indices 3 and 5, both odd ⇒ `drive_right`. Mirror of the left bogie.
        def Xform "Motor_MR" (
            prepend references = @lunco://components/mobility/motor.usda@</Motor>
        )
        {
            double3 xformOp:translate = (-0.3, -0.2, -0.4)
            uniform token[] xformOpOrder = ["xformOp:translate"]
            prepend rel lunco:motor:drivenWheel = </RockerBogie/BogieR/Wheel_MR>
            float inputs:demand.connect = </RockerBogie.outputs:drive_right>
        }

        def Xform "Gearbox_MR" (
            prepend references = @lunco://components/mobility/gearbox.usda@</Gearbox>
        )
        {
            double3 xformOp:translate = (-0.15, -0.2, -0.4)
            uniform token[] xformOpOrder = ["xformOp:translate"]
            float inputs:torque.connect = </RockerBogie/BogieR/Motor_MR.outputs:torque>
        }

        def Xform "Motor_RR" (
            prepend references = @lunco://components/mobility/motor.usda@</Motor>
        )
        {
            double3 xformOp:translate = (-0.3, -0.2, 0.6)
            uniform token[] xformOpOrder = ["xformOp:translate"]
            prepend rel lunco:motor:drivenWheel = </RockerBogie/BogieR/Wheel_RR>
            float inputs:demand.connect = </RockerBogie.outputs:drive_right>
        }

        def Xform "Gearbox_RR" (
            prepend references = @lunco://components/mobility/gearbox.usda@</Gearbox>
        )
        {
            double3 xformOp:translate = (-0.15, -0.2, 0.6)
            uniform token[] xformOpOrder = ["xformOp:translate"]
            float inputs:torque.connect = </RockerBogie/BogieR/Motor_RR.outputs:torque>
        }
    }

    # All joints below DELIBERATELY omit `physics:localPos0`/`localPos1`: each body's
    # placement is already its `xformOp:translate`, and the avian joint reader DERIVES
    # the anchor from the composed world poses (body1's origin in body0's rotation
    # frame; anchor on body1 = origin). This works for the sibling rocker↔bogie hinges
    # and the scaled hierarchy, so no anchor is typed — or left to drift — twice.
    # Author a `localPos0` on a joint to override the derivation.
    #
    # ── Lateral-axis revolute hinges (chassis ↔ rocker) ─────────────────────
    # HingeL/R: chassis <-> rocker joints.
    # NASA MER/MSL use mechanical stops limiting rocker travel to +/-30 to +/-45 degrees.
    # We use +/-30 degrees to keep the chassis level and prevent differential lockup.
    def PhysicsRevoluteJoint "HingeL" (
        doc = "Chassis-to-rocker hinge. Limited to +/-30 deg to match NASA mechanical stops, preventing excessive chassis roll and differential lockup."
    )
    {
        rel physics:body0 = </RockerBogie>
        rel physics:body1 = </RockerBogie/RockerL>
        uniform token physics:axis = "X"
        float physics:lowerLimit = -30
        float physics:upperLimit = 30
    }
    def PhysicsRevoluteJoint "HingeR" (
        doc = "Chassis-to-rocker hinge. Limited to +/-30 deg to match NASA mechanical stops, preventing excessive chassis roll and differential lockup."
    )
    {
        rel physics:body0 = </RockerBogie>
        rel physics:body1 = </RockerBogie/RockerR>
        uniform token physics:axis = "X"
        float physics:lowerLimit = -30
        float physics:upperLimit = 30
    }

    # ── Differential coupling (rocker-bogie holonomic constraint) ───────────
    # The standard PhysX gear joint over the two chassis↔rocker hinges: it softly
    # couples θ_left + θ_right → restSum (the drive's targetPosition), so the chassis
    # pitch tracks the rocker average instead of flopping on a free pitch DOF. A rigid
    # gear would fight the terrain and chatter, so the compliance is the joint's own
    # angular PhysicsDriveAPI (a strong spring-damper), not an ideal constraint.
    #   stiffness — how strongly the rockers mirror each other (default 15000)
    #   damping   — kills differential oscillation (default 1500)
    #   targetPosition — symmetric rest sum (0 rad)
    def PhysxPhysicsGearJoint "Differential" (
        prepend apiSchemas = ["PhysicsDriveAPI:angular"]
    )
    {
        rel physxGearJoint:hinge0 = </RockerBogie/HingeL>
        rel physxGearJoint:hinge1 = </RockerBogie/HingeR>
        float physxGearJoint:gearRatio = -1.0
        float drive:angular:physics:targetPosition = 0.0
        float drive:angular:physics:stiffness = 15000.0
        float drive:angular:physics:damping = 1500.0
    }

    # ── Lateral-axis revolute hinges (rocker ↔ bogie) ───────────────────────
    # BogieHingeL/R: rocker <-> bogie joints.
    # NASA rovers limit bogie rotation to +/-20 to +/-30 degrees to prevent the
    # middle/rear wheels from colliding with the rocker frame or chassis belly.
    # We use +/-20 degrees as a safe operating envelope.
    def PhysicsRevoluteJoint "BogieHingeL" (
        doc = "Rocker-to-bogie hinge. Limited to +/-20 deg to match NASA stops, preventing middle/rear wheels from colliding with the rocker frame."
    )
    {
        rel physics:body0 = </RockerBogie/RockerL>
        rel physics:body1 = </RockerBogie/BogieL>
        uniform token physics:axis = "X"
        float physics:lowerLimit = -20
        float physics:upperLimit = 20
    }
    def PhysicsRevoluteJoint "BogieHingeR" (
        doc = "Rocker-to-bogie hinge. Limited to +/-20 deg to match NASA stops, preventing middle/rear wheels from colliding with the rocker frame."
    )
    {
        rel physics:body0 = </RockerBogie/RockerR>
        rel physics:body1 = </RockerBogie/BogieR>
        uniform token physics:axis = "X"
        float physics:lowerLimit = -20
        float physics:upperLimit = 20
    }

    # ── Wheel revolute joints (rocker/bogie ↔ wheel) ────────────────────────
    # The joint is the motor's OUTPUT COUPLING, not the motor: it carries
    # `PhysicsDriveAPI:angular`, the drive `type` and the axis, and NOTHING ELSE.
    # `maxForce` and `targetVelocity` are deliberately absent — the loader writes
    # them from the `Motor_*` / `Gearbox_*` pair that names this joint's WHEEL via
    # `lunco:motor:drivenWheel` — the loader follows wheel → joint to get here — so the
    # torque ceiling is stated once, on the part that makes the torque, instead of being
    # typed here as a second opinion.
    def PhysicsRevoluteJoint "Wheel_FL_Hinge" (
        prepend apiSchemas = ["PhysicsDriveAPI:angular"]
    )
    {
        rel physics:body0 = </RockerBogie/RockerL>
        rel physics:body1 = </RockerBogie/RockerL/Wheel_FL>
        uniform token physics:axis = "X"
        uniform token drive:angular:physics:type = "force"
    }

    def PhysicsRevoluteJoint "Wheel_FR_Hinge" (
        prepend apiSchemas = ["PhysicsDriveAPI:angular"]
    )
    {
        rel physics:body0 = </RockerBogie/RockerR>
        rel physics:body1 = </RockerBogie/RockerR/Wheel_FR>
        uniform token physics:axis = "X"
        uniform token drive:angular:physics:type = "force"
    }

    def PhysicsRevoluteJoint "Wheel_ML_Hinge" (
        prepend apiSchemas = ["PhysicsDriveAPI:angular"]
    )
    {
        rel physics:body0 = </RockerBogie/BogieL>
        rel physics:body1 = </RockerBogie/BogieL/Wheel_ML>
        uniform token physics:axis = "X"
        uniform token drive:angular:physics:type = "force"
    }

    def PhysicsRevoluteJoint "Wheel_MR_Hinge" (
        prepend apiSchemas = ["PhysicsDriveAPI:angular"]
    )
    {
        rel physics:body0 = </RockerBogie/BogieR>
        rel physics:body1 = </RockerBogie/BogieR/Wheel_MR>
        uniform token physics:axis = "X"
        uniform token drive:angular:physics:type = "force"
    }

    def PhysicsRevoluteJoint "Wheel_RL_Hinge" (
        prepend apiSchemas = ["PhysicsDriveAPI:angular"]
    )
    {
        rel physics:body0 = </RockerBogie/BogieL>
        rel physics:body1 = </RockerBogie/BogieL/Wheel_RL>
        uniform token physics:axis = "X"
        uniform token drive:angular:physics:type = "force"
    }

    def PhysicsRevoluteJoint "Wheel_RR_Hinge" (
        prepend apiSchemas = ["PhysicsDriveAPI:angular"]
    )
    {
        rel physics:body0 = </RockerBogie/BogieR>
        rel physics:body1 = </RockerBogie/BogieR/Wheel_RR>
        uniform token physics:axis = "X"
        uniform token drive:angular:physics:type = "force"
    }

    # --- Drive law -----------------------------------------------------------
    # HOW throttle/steer become per-side drive is COMPOSITION, not an
    # enumeration. The plain authored state is the instant built-in skid kernel
    # (`PhysxVehicleTankDifferentialAPI` above). For a solver-clocked per-side
    # motor lag, compose on the SAME skid law the other skid rovers use:
    #
    #   def "Rover" (
    #       prepend references = [
    #           @lunco://vessels/rovers/rocker_bogie.usda@</RockerBogie>,
    #           @lunco://components/mobility/drive_laws/modelica_skid.usda@</DriveLaw>,
    #       ]
    #   ) {}
    #
    # The wheels here carry no `lunco:drivePort`, so they use the index-parity
    # default (even 0/2/4 = FL/ML/RL ⇒ drive_left, odd 1/3/5 = FR/MR/RR ⇒
    # drive_right) — exactly the port pair the skid law writes.
}
